<class 'dataactcore.utils.responseException.ResponseException'>Prerequisites incomplete, job cannot be started[('C:\\Users\\jworcest\\Documents\\dataactvalidator\\dataactvalidator\\validation_handlers\\validationManager.py', 220, 'validateJob', 'if(not (jobTracker.runChecks(jobId))):'), ('C:\\Users\\jworcest\\Documents\\dataactvalidator\\dataactvalidator\\interfaces\\jobTrackerInterface.py', 18, 'runChecks', 'if(self.checkJobReady(jobId) and self.checkPrerequisites(jobId) and self.checkJobType(jobId)):'), ('C:\\Users\\jworcest\\Documents\\dataactvalidator\\dataactvalidator\\interfaces\\jobTrackerInterface.py', 64, 'checkPrerequisites', 'raise ResponseException("Prerequisites incomplete, job cannot be started",StatusCode.CLIENT_ERROR,None,ValidationError.jobError)')]<class 'dataactcore.utils.responseException.ResponseException'>Wrong type of job for this service[('C:\\Users\\jworcest\\Documents\\dataactvalidator\\dataactvalidator\\validation_handlers\\validationManager.py', 220, 'validateJob', 'if(not (jobTracker.runChecks(jobId))):'), ('C:\\Users\\jworcest\\Documents\\dataactvalidator\\dataactvalidator\\interfaces\\jobTrackerInterface.py', 18, 'runChecks', 'if(self.checkJobReady(jobId) and self.checkPrerequisites(jobId) and self.checkJobType(jobId)):'), ('C:\\Users\\jworcest\\Documents\\dataactvalidator\\dataactvalidator\\interfaces\\jobTrackerInterface.py', 100, 'checkJobType', 'raise ResponseException("Wrong type of job for this service",StatusCode.CLIENT_ERROR,None,ValidationError.jobError)')]<class 'dataactcore.utils.responseException.ResponseException'>Job ID not found in job_status table[('C:\\Users\\jworcest\\Documents\\dataactvalidator\\dataactvalidator\\validation_handlers\\validationManager.py', 220, 'validateJob', 'if(not (jobTracker.runChecks(jobId))):'), ('C:\\Users\\jworcest\\Documents\\dataactvalidator\\dataactvalidator\\interfaces\\jobTrackerInterface.py', 18, 'runChecks', 'if(self.checkJobReady(jobId) and self.checkPrerequisites(jobId) and self.checkJobType(jobId)):'), ('C:\\Users\\jworcest\\Documents\\dataactvalidator\\dataactvalidator\\interfaces\\jobTrackerInterface.py', 33, 'checkJobReady', 'if(self.checkJobUnique(queryResult)):'), ('C:\\Users\\jworcest\\Documents\\dataactcore\\dataactcore\\models\\jobTrackerInterface.py', 39, 'checkJobUnique', 'return BaseInterface.checkUnique(queryResult, "Job ID not found in job_status table","Conflicting jobs found for this ID")'), ('C:\\Users\\jworcest\\Documents\\dataactcore\\dataactcore\\models\\baseInterface.py', 72, 'checkUnique', 'raise ResponseException(noResultMessage,StatusCode.CLIENT_ERROR,NoResultFound,10)')]<class 'dataactcore.utils.responseException.ResponseException'>Header : walrus not in CSV schema[('C:\\Users\\jworcest\\Documents\\dataactvalidator\\dataactvalidator\\validation_handlers\\validationManager.py', 238, 'validateJob', 'self.runValidation(jobId,jobTracker)'), ('C:\\Users\\jworcest\\Documents\\dataactvalidator\\dataactvalidator\\validation_handlers\\validationManager.py', 135, 'runValidation', 'reader.openFile(bucketName, fileName,fieldList)'), ('C:\\Users\\jworcest\\Documents\\dataactvalidator\\dataactvalidator\\filestreaming\\csvReader.py', 52, 'openFile', 'raise ResponseException(("Header : "+ headerValue + " not in CSV schema"), StatusCode.CLIENT_ERROR, ValueError,ValidationError.badHeaderError)')]<class 'dataactcore.utils.responseException.ResponseException'>CSV file must have a header[('C:\\Users\\jworcest\\Documents\\dataactvalidator\\dataactvalidator\\validation_handlers\\validationManager.py', 238, 'validateJob', 'self.runValidation(jobId,jobTracker)'), ('C:\\Users\\jworcest\\Documents\\dataactvalidator\\dataactvalidator\\validation_handlers\\validationManager.py', 135, 'runValidation', 'reader.openFile(bucketName, fileName,fieldList)'), ('C:\\Users\\jworcest\\Documents\\dataactvalidator\\dataactvalidator\\filestreaming\\csvReader.py', 45, 'openFile', 'raise ResponseException("CSV file must have a header",StatusCode.CLIENT_ERROR,ValueError,ValidationError.singleRow)')]<class 'dataactcore.utils.responseException.ResponseException'>Header : header_5 is required[('C:\\Users\\jworcest\\Documents\\dataactvalidator\\dataactvalidator\\validation_handlers\\validationManager.py', 238, 'validateJob', 'self.runValidation(jobId,jobTracker)'), ('C:\\Users\\jworcest\\Documents\\dataactvalidator\\dataactvalidator\\validation_handlers\\validationManager.py', 135, 'runValidation', 'reader.openFile(bucketName, fileName,fieldList)'), ('C:\\Users\\jworcest\\Documents\\dataactvalidator\\dataactvalidator\\filestreaming\\csvReader.py', 62, 'openFile', 'raise ResponseException(("Header : "+ schema.name + " is required"), StatusCode.CLIENT_ERROR, ValueError,ValidationError.missingHeaderError)')]<class 'dataactcore.utils.responseException.ResponseException'>Prerequisites incomplete, job cannot be started[('C:\\Users\\jworcest\\Documents\\dataactvalidator\\dataactvalidator\\validation_handlers\\validationManager.py', 220, 'validateJob', 'if(not (jobTracker.runChecks(jobId))):'), ('C:\\Users\\jworcest\\Documents\\dataactvalidator\\dataactvalidator\\interfaces\\jobTrackerInterface.py', 18, 'runChecks', 'if(self.checkJobReady(jobId) and self.checkPrerequisites(jobId) and self.checkJobType(jobId)):'), ('C:\\Users\\jworcest\\Documents\\dataactvalidator\\dataactvalidator\\interfaces\\jobTrackerInterface.py', 64, 'checkPrerequisites', 'raise ResponseException("Prerequisites incomplete, job cannot be started",StatusCode.CLIENT_ERROR,None,ValidationError.jobError)')]<class 'dataactcore.utils.responseException.ResponseException'>Wrong type of job for this service[('C:\\Users\\jworcest\\Documents\\dataactvalidator\\dataactvalidator\\validation_handlers\\validationManager.py', 220, 'validateJob', 'if(not (jobTracker.runChecks(jobId))):'), ('C:\\Users\\jworcest\\Documents\\dataactvalidator\\dataactvalidator\\interfaces\\jobTrackerInterface.py', 18, 'runChecks', 'if(self.checkJobReady(jobId) and self.checkPrerequisites(jobId) and self.checkJobType(jobId)):'), ('C:\\Users\\jworcest\\Documents\\dataactvalidator\\dataactvalidator\\interfaces\\jobTrackerInterface.py', 100, 'checkJobType', 'raise ResponseException("Wrong type of job for this service",StatusCode.CLIENT_ERROR,None,ValidationError.jobError)')]<class 'dataactcore.utils.responseException.ResponseException'>Job ID not found in job_status table[('C:\\Users\\jworcest\\Documents\\dataactvalidator\\dataactvalidator\\validation_handlers\\validationManager.py', 220, 'validateJob', 'if(not (jobTracker.runChecks(jobId))):'), ('C:\\Users\\jworcest\\Documents\\dataactvalidator\\dataactvalidator\\interfaces\\jobTrackerInterface.py', 18, 'runChecks', 'if(self.checkJobReady(jobId) and self.checkPrerequisites(jobId) and self.checkJobType(jobId)):'), ('C:\\Users\\jworcest\\Documents\\dataactvalidator\\dataactvalidator\\interfaces\\jobTrackerInterface.py', 33, 'checkJobReady', 'if(self.checkJobUnique(queryResult)):'), ('C:\\Users\\jworcest\\Documents\\dataactcore\\dataactcore\\models\\jobTrackerInterface.py', 39, 'checkJobUnique', 'return BaseInterface.checkUnique(queryResult, "Job ID not found in job_status table","Conflicting jobs found for this ID")'), ('C:\\Users\\jworcest\\Documents\\dataactcore\\dataactcore\\models\\baseInterface.py', 72, 'checkUnique', 'raise ResponseException(noResultMessage,StatusCode.CLIENT_ERROR,NoResultFound,10)')]<class 'dataactcore.utils.responseException.ResponseException'>Header : walrus not in CSV schema[('C:\\Users\\jworcest\\Documents\\dataactvalidator\\dataactvalidator\\validation_handlers\\validationManager.py', 238, 'validateJob', 'self.runValidation(jobId,jobTracker)'), ('C:\\Users\\jworcest\\Documents\\dataactvalidator\\dataactvalidator\\validation_handlers\\validationManager.py', 135, 'runValidation', 'reader.openFile(bucketName, fileName,fieldList)'), ('C:\\Users\\jworcest\\Documents\\dataactvalidator\\dataactvalidator\\filestreaming\\csvReader.py', 52, 'openFile', 'raise ResponseException(("Header : "+ headerValue + " not in CSV schema"), StatusCode.CLIENT_ERROR, ValueError,ValidationError.badHeaderError)')]<class 'dataactcore.utils.responseException.ResponseException'>CSV file must have a header[('C:\\Users\\jworcest\\Documents\\dataactvalidator\\dataactvalidator\\validation_handlers\\validationManager.py', 238, 'validateJob', 'self.runValidation(jobId,jobTracker)'), ('C:\\Users\\jworcest\\Documents\\dataactvalidator\\dataactvalidator\\validation_handlers\\validationManager.py', 135, 'runValidation', 'reader.openFile(bucketName, fileName,fieldList)'), ('C:\\Users\\jworcest\\Documents\\dataactvalidator\\dataactvalidator\\filestreaming\\csvReader.py', 45, 'openFile', 'raise ResponseException("CSV file must have a header",StatusCode.CLIENT_ERROR,ValueError,ValidationError.singleRow)')]<class 'dataactcore.utils.responseException.ResponseException'>Header : header_5 is required[('C:\\Users\\jworcest\\Documents\\dataactvalidator\\dataactvalidator\\validation_handlers\\validationManager.py', 238, 'validateJob', 'self.runValidation(jobId,jobTracker)'), ('C:\\Users\\jworcest\\Documents\\dataactvalidator\\dataactvalidator\\validation_handlers\\validationManager.py', 135, 'runValidation', 'reader.openFile(bucketName, fileName,fieldList)'), ('C:\\Users\\jworcest\\Documents\\dataactvalidator\\dataactvalidator\\filestreaming\\csvReader.py', 62, 'openFile', 'raise ResponseException(("Header : "+ schema.name + " is required"), StatusCode.CLIENT_ERROR, ValueError,ValidationError.missingHeaderError)')]<class 'dataactcore.utils.responseException.ResponseException'>Prerequisites incomplete, job cannot be started[('C:/Users/jworcest/Documents/dataactvalidator/dataactvalidator/app.py', 62, 'validate_threaded', 'manager.testJobID(jobId)'), ('C:\\Users\\jworcest\\Documents\\dataactvalidator\\dataactvalidator\\validation_handlers\\validationManager.py', 73, 'testJobID', 'if(not (InterfaceHolder.JOB_TRACKER.runChecks(jobId))):'), ('C:\\Users\\jworcest\\Documents\\dataactvalidator\\dataactvalidator\\interfaces\\jobTrackerInterface.py', 18, 'runChecks', 'if(self.checkJobReady(jobId) and self.checkPrerequisites(jobId) and self.checkJobType(jobId)):'), ('C:\\Users\\jworcest\\Documents\\dataactvalidator\\dataactvalidator\\interfaces\\jobTrackerInterface.py', 64, 'checkPrerequisites', 'raise ResponseException("Prerequisites incomplete, job cannot be started",StatusCode.CLIENT_ERROR,None,ValidationError.jobError)')]<class 'dataactcore.utils.responseException.ResponseException'>Wrong type of job for this service[('C:/Users/jworcest/Documents/dataactvalidator/dataactvalidator/app.py', 62, 'validate_threaded', 'manager.testJobID(jobId)'), ('C:\\Users\\jworcest\\Documents\\dataactvalidator\\dataactvalidator\\validation_handlers\\validationManager.py', 73, 'testJobID', 'if(not (InterfaceHolder.JOB_TRACKER.runChecks(jobId))):'), ('C:\\Users\\jworcest\\Documents\\dataactvalidator\\dataactvalidator\\interfaces\\jobTrackerInterface.py', 18, 'runChecks', 'if(self.checkJobReady(jobId) and self.checkPrerequisites(jobId) and self.checkJobType(jobId)):'), ('C:\\Users\\jworcest\\Documents\\dataactvalidator\\dataactvalidator\\interfaces\\jobTrackerInterface.py', 100, 'checkJobType', 'raise ResponseException("Wrong type of job for this service",StatusCode.CLIENT_ERROR,None,ValidationError.jobError)')]<class 'dataactcore.utils.responseException.ResponseException'>Job ID not found in job_status table[('C:/Users/jworcest/Documents/dataactvalidator/dataactvalidator/app.py', 62, 'validate_threaded', 'manager.testJobID(jobId)'), ('C:\\Users\\jworcest\\Documents\\dataactvalidator\\dataactvalidator\\validation_handlers\\validationManager.py', 73, 'testJobID', 'if(not (InterfaceHolder.JOB_TRACKER.runChecks(jobId))):'), ('C:\\Users\\jworcest\\Documents\\dataactvalidator\\dataactvalidator\\interfaces\\jobTrackerInterface.py', 18, 'runChecks', 'if(self.checkJobReady(jobId) and self.checkPrerequisites(jobId) and self.checkJobType(jobId)):'), ('C:\\Users\\jworcest\\Documents\\dataactvalidator\\dataactvalidator\\interfaces\\jobTrackerInterface.py', 33, 'checkJobReady', 'if(self.checkJobUnique(queryResult)):'), ('C:\\Users\\jworcest\\Documents\\dataactcore\\dataactcore\\models\\jobTrackerInterface.py', 39, 'checkJobUnique', 'return BaseInterface.checkUnique(queryResult, "Job ID not found in job_status table","Conflicting jobs found for this ID")'), ('C:\\Users\\jworcest\\Documents\\dataactcore\\dataactcore\\models\\baseInterface.py', 72, 'checkUnique', 'raise ResponseException(noResultMessage,StatusCode.CLIENT_ERROR,NoResultFound,10)')]<class 'dataactcore.utils.responseException.ResponseException'>Prerequisites incomplete, job cannot be started[('C:/Users/jworcest/Documents/dataactvalidator/dataactvalidator/app.py', 62, 'validate_threaded', 'manager.testJobID(jobId)'), ('C:\\Users\\jworcest\\Documents\\dataactvalidator\\dataactvalidator\\validation_handlers\\validationManager.py', 73, 'testJobID', 'if(not (InterfaceHolder.JOB_TRACKER.runChecks(jobId))):'), ('C:\\Users\\jworcest\\Documents\\dataactvalidator\\dataactvalidator\\interfaces\\jobTrackerInterface.py', 18, 'runChecks', 'if(self.checkJobReady(jobId) and self.checkPrerequisites(jobId) and self.checkJobType(jobId)):'), ('C:\\Users\\jworcest\\Documents\\dataactvalidator\\dataactvalidator\\interfaces\\jobTrackerInterface.py', 64, 'checkPrerequisites', 'raise ResponseException("Prerequisites incomplete, job cannot be started",StatusCode.CLIENT_ERROR,None,ValidationError.jobError)')]<class 'dataactcore.utils.responseException.ResponseException'>Wrong type of job for this service[('C:/Users/jworcest/Documents/dataactvalidator/dataactvalidator/app.py', 62, 'validate_threaded', 'manager.testJobID(jobId)'), ('C:\\Users\\jworcest\\Documents\\dataactvalidator\\dataactvalidator\\validation_handlers\\validationManager.py', 73, 'testJobID', 'if(not (InterfaceHolder.JOB_TRACKER.runChecks(jobId))):'), ('C:\\Users\\jworcest\\Documents\\dataactvalidator\\dataactvalidator\\interfaces\\jobTrackerInterface.py', 18, 'runChecks', 'if(self.checkJobReady(jobId) and self.checkPrerequisites(jobId) and self.checkJobType(jobId)):'), ('C:\\Users\\jworcest\\Documents\\dataactvalidator\\dataactvalidator\\interfaces\\jobTrackerInterface.py', 100, 'checkJobType', 'raise ResponseException("Wrong type of job for this service",StatusCode.CLIENT_ERROR,None,ValidationError.jobError)')]<class 'dataactcore.utils.responseException.ResponseException'>Job ID not found in job_status table[('C:/Users/jworcest/Documents/dataactvalidator/dataactvalidator/app.py', 62, 'validate_threaded', 'manager.testJobID(jobId)'), ('C:\\Users\\jworcest\\Documents\\dataactvalidator\\dataactvalidator\\validation_handlers\\validationManager.py', 73, 'testJobID', 'if(not (InterfaceHolder.JOB_TRACKER.runChecks(jobId))):'), ('C:\\Users\\jworcest\\Documents\\dataactvalidator\\dataactvalidator\\interfaces\\jobTrackerInterface.py', 18, 'runChecks', 'if(self.checkJobReady(jobId) and self.checkPrerequisites(jobId) and self.checkJobType(jobId)):'), ('C:\\Users\\jworcest\\Documents\\dataactvalidator\\dataactvalidator\\interfaces\\jobTrackerInterface.py', 33, 'checkJobReady', 'if(self.checkJobUnique(queryResult)):'), ('C:\\Users\\jworcest\\Documents\\dataactcore\\dataactcore\\models\\jobTrackerInterface.py', 39, 'checkJobUnique', 'return BaseInterface.checkUnique(queryResult, "Job ID not found in job_status table","Conflicting jobs found for this ID")'), ('C:\\Users\\jworcest\\Documents\\dataactcore\\dataactcore\\models\\baseInterface.py', 72, 'checkUnique', 'raise ResponseException(noResultMessage,StatusCode.CLIENT_ERROR,NoResultFound,10)')]<class 'dataactcore.utils.responseException.ResponseException'>Prerequisites incomplete, job cannot be started[('C:\\Users\\jworcest\\Documents\\dataactvalidator\\dataactvalidator\\validation_handlers\\validationManager.py', 223, 'validateJob', 'if(not (jobTracker.runChecks(jobId))):'), ('C:\\Users\\jworcest\\Documents\\dataactvalidator\\dataactvalidator\\interfaces\\jobTrackerInterface.py', 18, 'runChecks', 'if(self.checkJobReady(jobId) and self.checkPrerequisites(jobId) and self.checkJobType(jobId)):'), ('C:\\Users\\jworcest\\Documents\\dataactvalidator\\dataactvalidator\\interfaces\\jobTrackerInterface.py', 64, 'checkPrerequisites', 'raise ResponseException("Prerequisites incomplete, job cannot be started",StatusCode.CLIENT_ERROR,None,ValidationError.jobError)')]<class 'dataactcore.utils.responseException.ResponseException'>Wrong type of job for this service[('C:\\Users\\jworcest\\Documents\\dataactvalidator\\dataactvalidator\\validation_handlers\\validationManager.py', 223, 'validateJob', 'if(not (jobTracker.runChecks(jobId))):'), ('C:\\Users\\jworcest\\Documents\\dataactvalidator\\dataactvalidator\\interfaces\\jobTrackerInterface.py', 18, 'runChecks', 'if(self.checkJobReady(jobId) and self.checkPrerequisites(jobId) and self.checkJobType(jobId)):'), ('C:\\Users\\jworcest\\Documents\\dataactvalidator\\dataactvalidator\\interfaces\\jobTrackerInterface.py', 100, 'checkJobType', 'raise ResponseException("Wrong type of job for this service",StatusCode.CLIENT_ERROR,None,ValidationError.jobError)')]<class 'dataactcore.utils.responseException.ResponseException'>Job ID not found in job_status table[('C:\\Users\\jworcest\\Documents\\dataactvalidator\\dataactvalidator\\validation_handlers\\validationManager.py', 223, 'validateJob', 'if(not (jobTracker.runChecks(jobId))):'), ('C:\\Users\\jworcest\\Documents\\dataactvalidator\\dataactvalidator\\interfaces\\jobTrackerInterface.py', 18, 'runChecks', 'if(self.checkJobReady(jobId) and self.checkPrerequisites(jobId) and self.checkJobType(jobId)):'), ('C:\\Users\\jworcest\\Documents\\dataactvalidator\\dataactvalidator\\interfaces\\jobTrackerInterface.py', 33, 'checkJobReady', 'if(self.checkJobUnique(queryResult)):'), ('C:\\Users\\jworcest\\Documents\\dataactcore\\dataactcore\\models\\jobTrackerInterface.py', 39, 'checkJobUnique', 'return BaseInterface.checkUnique(queryResult, "Job ID not found in job_status table","Conflicting jobs found for this ID")'), ('C:\\Users\\jworcest\\Documents\\dataactcore\\dataactcore\\models\\baseInterface.py', 72, 'checkUnique', 'raise ResponseException(noResultMessage,StatusCode.CLIENT_ERROR,NoResultFound,10)')]<class 'dataactcore.utils.responseException.ResponseException'>Header : walrus not in CSV schema[('C:\\Users\\jworcest\\Documents\\dataactvalidator\\dataactvalidator\\validation_handlers\\validationManager.py', 241, 'validateJob', 'self.runValidation(jobId,interfaces)'), ('C:\\Users\\jworcest\\Documents\\dataactvalidator\\dataactvalidator\\validation_handlers\\validationManager.py', 137, 'runValidation', 'reader.openFile(bucketName, fileName,fieldList)'), ('C:\\Users\\jworcest\\Documents\\dataactvalidator\\dataactvalidator\\filestreaming\\csvReader.py', 52, 'openFile', 'raise ResponseException(("Header : "+ headerValue + " not in CSV schema"), StatusCode.CLIENT_ERROR, ValueError,ValidationError.badHeaderError)')]<class 'dataactcore.utils.responseException.ResponseException'>CSV file must have a header[('C:\\Users\\jworcest\\Documents\\dataactvalidator\\dataactvalidator\\validation_handlers\\validationManager.py', 241, 'validateJob', 'self.runValidation(jobId,interfaces)'), ('C:\\Users\\jworcest\\Documents\\dataactvalidator\\dataactvalidator\\validation_handlers\\validationManager.py', 137, 'runValidation', 'reader.openFile(bucketName, fileName,fieldList)'), ('C:\\Users\\jworcest\\Documents\\dataactvalidator\\dataactvalidator\\filestreaming\\csvReader.py', 45, 'openFile', 'raise ResponseException("CSV file must have a header",StatusCode.CLIENT_ERROR,ValueError,ValidationError.singleRow)')]<class 'dataactcore.utils.responseException.ResponseException'>Header : header_5 is required[('C:\\Users\\jworcest\\Documents\\dataactvalidator\\dataactvalidator\\validation_handlers\\validationManager.py', 241, 'validateJob', 'self.runValidation(jobId,interfaces)'), ('C:\\Users\\jworcest\\Documents\\dataactvalidator\\dataactvalidator\\validation_handlers\\validationManager.py', 137, 'runValidation', 'reader.openFile(bucketName, fileName,fieldList)'), ('C:\\Users\\jworcest\\Documents\\dataactvalidator\\dataactvalidator\\filestreaming\\csvReader.py', 62, 'openFile', 'raise ResponseException(("Header : "+ schema.name + " is required"), StatusCode.CLIENT_ERROR, ValueError,ValidationError.missingHeaderError)')]